<?xml version='1.0' encoding='utf-8'?>
<robot name="snow_white_v2">

<link name="base_link">
    <inertial>
        <origin xyz="-0.8261770190626948 -0.00019821739984704248 0.21183805471824457" rpy="0.0 0.0 0.0" />
        <mass value="45.73232846140426" />
        <inertia ixx="0.8539391644599861" iyy="2.7634753674571044" izz="2.7032696043021645" ixy="0.11965391815080577" iyz="0.000426686767311116" ixz="0.005747682139000787" />
    </inertial>
    <visual name="base_link">
        <origin xyz="0.0 0.0 0.0" rpy="0.0 0.0 0.0" />
        <geometry>
            <mesh filename="file://$(find snow_white_description)/src/description/Chassis.stl" scale="0.001 0.001 0.001" />
        </geometry>
    </visual>
    <collision name="Chassis_collision">
        <origin xyz="0.0 0.0 0.0" rpy="0.0 0.0 0.0" />
        <geometry>
            <mesh filename="file://$(find snow_white_description)/src/description/Chassis.stl" scale="0.001 0.001 0.001" />
        </geometry>
    </collision>
</link>

<gazebo reference="base_link">
  
  <mu1>0.2</mu1>
  <mu2>0.2</mu2>
  <self_collide>true</self_collide>
  <gravity>true</gravity>
</gazebo>

<link name="base_footprint"/>
<joint name="base_joint" type="fixed">
    <parent link="base_link"/>
    <child link="base_footprint"/>
    <origin xyz="-0.8261770190626948 -0.00019821739984704248 0" rpy="0.0 0.0 0.0"/>
</joint>
<!--The inertial origin is the center of inertia. We set the joint origin as this center of inertia,-->
<!--And then we flip the signs on that origin and paste into the origins for the visuals and collisions.-->
<link name="rear_left_wheel_link">
    <inertial>
        <origin xyz="-1.1655260760350041 0.27536793106901175 0.14474750000000006" rpy="0.0 0.0 0.0" />
        <mass value="8.74447617217798" />
        <inertia ixx="0.07871457468352261" iyy="0.13666503945071362" izz="0.07871453816891716" ixy="-9.769962616701378e-15" iyz="1.2212453270876722e-15" ixz="-2.2872250760030965e-08" />
    </inertial>
    <visual name="rear_left_wheel_visual">
        <origin xyz="1.1655260760350041 -0.27536793106901175 -0.14474750000000006" rpy="0.0 0.0 0.0" />
        <geometry>
            <mesh filename="file://$(find snow_white_description)/src/description/rear_left_wheel.stl" scale="0.001 0.001 0.001" />
        </geometry>
    </visual>
    <collision name="rear_left_wheel_collision">
        <origin xyz="1.1655260760350041 -0.27536793106901175 -0.14474750000000006" rpy="0.0 0.0 0.0" />
        <geometry>
            <mesh filename="file://$(find snow_white_description)/src/description/rear_left_wheel.stl" scale="0.001 0.001 0.001" />
        </geometry>
    </collision>
</link>

<joint name="rear_left_wheel_joint" type="continuous">
    <parent link="base_link"/>
    <child link="rear_left_wheel_link"/>
    <origin xyz="-1.1655260760350041 0.27536793106901175 0.14474750000000006"/>
    <axis xyz="0 1 0"/>
</joint>

<gazebo reference="rear_left_wheel_link">
  <mu1>0.2</mu1>
  <mu2>0.2</mu2>
  <self_collide>true</self_collide>
  <gravity>true</gravity>
</gazebo>

<link name="rear_right_wheel_link">
    <inertial>
        <origin xyz="-1.1655260760350006 -0.27536793106455426 0.14474750000000006" rpy="0.0 0.0 0.0" />
        <mass value="8.744476172219155" />
        <inertia ixx="0.07871458445823654" iyy="0.13666503945075448" izz="0.07871452839432713" ixy="8.881784197001252e-16" iyz="-3.3306690738754696e-16" ixz="-8.406998208698724e-09" />
    </inertial>
    <visual name="rear_right_wheel_visual">
        <origin xyz="1.1655260760350006 0.27536793106455426 -0.14474750000000006" rpy="0.0 0.0 0.0" />
        <geometry>
            <mesh filename="file://$(find snow_white_description)/src/description/rear_right_wheel.stl" scale="0.001 0.001 0.001" />
        </geometry>
    </visual>
    <collision name="rear_right_wheel_collision">
        <origin xyz="1.1655260760350006 0.27536793106455426 -0.14474750000000006" rpy="0.0 0.0 0.0" />
        <geometry>
            <mesh filename="file://$(find snow_white_description)/src/description/rear_right_wheel.stl" scale="0.001 0.001 0.001" />
        </geometry>
    </collision>
</link>

<joint name="rear_right_wheel_joint" type="continuous">
    <parent link="base_link"/>
    <child link="rear_right_wheel_link"/>
    <origin xyz="-1.1655260760350006 -0.27536793106455426 0.14474750000000006"/>
    <axis xyz="0 1 0"/>
</joint>

<gazebo reference="rear_right_wheel_link">
  <mu1>0.2</mu1>
  <mu2>0.2</mu2>
  <self_collide>true</self_collide>
  <gravity>true</gravity>
</gazebo>

<link name="front_left_wheel_link">
    <inertial>
        <origin xyz="-0.47912597751770164 0.27536793106894875 0.1447475000000005" rpy="0.0 0.0 0.0" />
        <mass value="8.744476172214625" />
        <inertia ixx="0.07871458445822932" iyy="0.1366650394507527" izz="0.07871452839432358" ixy="-3.774758283725532e-15" iyz="1.2212453270876722e-15" ixz="8.406995211096557e-09" />
    </inertial>
    <visual name="front_left_wheel_visual">
        <origin xyz="0.47912597751770164 -0.27536793106894875 -0.1447475000000005" rpy="0.0 0.0 0.0" />
        <geometry>
            <mesh filename="file://$(find snow_white_description)/src/description/front_left_wheel.stl" scale="0.001 0.001 0.001" />
        </geometry>
    </visual>
    <collision name="front_left_wheel_collision">
        <origin xyz="0.47912597751770164 -0.27536793106894875 -0.1447475000000005" rpy="0.0 0.0 0.0" />
        <geometry>
            <mesh filename="file://$(find snow_white_description)/src/description/front_left_wheel.stl" scale="0.001 0.001 0.001" />
        </geometry>
    </collision>
</link>

<joint name="front_left_wheel_joint" type="continuous">
    <parent link="base_link"/>
    <child link="front_left_wheel_link"/>
    <origin xyz="-0.47912597751770164 0.27536793106894875 0.1447475000000005"/>
    <axis xyz="0 1 0"/>
</joint>

<gazebo reference="front_left_wheel_link">
  <mu1>0.2</mu1>
  <mu2>0.2</mu2>
  <self_collide>true</self_collide>
  <gravity>true</gravity>
</gazebo>

<link name="front_right_wheel_link">
    <inertial>
        <origin xyz="-0.47912597751770025 -0.2753679310644906 0.14474749999999975" rpy="0.0 0.0 0.0" />
        <mass value="8.744476172182637" />
        <inertia ixx="0.07871457468353005" iyy="0.13666503945075448" izz="0.07871453816896468" ixy="8.881784197001252e-16" iyz="-2.7755575615628914e-16" ixz="2.2872244320737423e-08" />
    </inertial>
    <visual name="front_right_wheel_visual">
        <origin xyz="0.47912597751770025 0.2753679310644906 -0.14474749999999975" rpy="0.0 0.0 0.0" />
        <geometry>
            <mesh filename="file://$(find snow_white_description)/src/description/front_right_wheel.stl" scale="0.001 0.001 0.001" />
        </geometry>
    </visual>
    <collision name="front_right_wheel_collision">
        <origin xyz="0.47912597751770025 0.2753679310644906 -0.14474749999999975" rpy="0.0 0.0 0.0" />
        <geometry>
            <mesh filename="file://$(find snow_white_description)/src/description/front_right_wheel.stl" scale="0.001 0.001 0.001" />
        </geometry>
    </collision>
</link>

<joint name="front_right_wheel_joint" type="continuous">
    <parent link="base_link"/>
    <child link="front_right_wheel_link"/>
    <origin xyz="-0.47912597751770025 -0.2753679310644906 0.14474749999999975"/>
    <axis xyz="0 1 0"/>
</joint>

<gazebo reference="front_right_wheel_link">
  <mu1>0.2</mu1>
  <mu2>0.2</mu2>
  <self_collide>true</self_collide>
  <gravity>true</gravity>
</gazebo>

<link name="rear_left_wheel_shaft_link">
    <inertial>
        <origin xyz="-1.1655106658181305 0.16733194473862242 0.14477951854361112" rpy="0.0 0.0 0.0" />
        <mass value="0.0834421822538061" />
        <inertia ixx="0.0006091354667322061" iyy="3.808007812688974e-06" izz="0.000609162424557344" ixy="9.130274918056625e-09" iyz="1.8970407919018106e-08" ixz="1.6886028049792334e-08" />
    </inertial>
    <visual name="rear_left_wheel_shaft_visual">
        <origin xyz="1.1655106658181305 -0.16733194473862242 -0.14477951854361112" rpy="0.0 0.0 0.0" />
        <geometry>
            <mesh filename="file://$(find snow_white_description)/src/description/rear_left_wheel_shaft.stl" scale="0.001 0.001 0.001" />
        </geometry>
    </visual>
    <collision name="rear_left_wheel_shaft_collision">
        <origin xyz="1.1655106658181305 -0.16733194473862242 -0.14477951854361112" rpy="0.0 0.0 0.0" />
        <geometry>
            <mesh filename="file://$(find snow_white_description)/src/description/rear_left_wheel_shaft.stl" scale="0.001 0.001 0.001" />
        </geometry>
    </collision>
</link>

<joint name="rear_left_wheel_shaft_joint" type="fixed">
    <parent link="base_link"/>
    <child link="rear_left_wheel_shaft_link"/>
    <origin xyz="-1.1655106658181305 0.16733194473862242 0.14477951854361112"/>
    <axis xyz="0 1 0"/>
</joint>

<gazebo reference="rear_left_wheel_shaft_link">
  <mu1>0.2</mu1>
  <mu2>0.2</mu2>
  <self_collide>true</self_collide>
  <gravity>true</gravity>
</gazebo>

<link name="front_left_wheel_shaft_link">
    <inertial>
        <origin xyz="-0.47912081895680636 0.1673319447386228 0.14471234211626394" rpy="0.0 0.0 0.0" />
        <mass value="0.08344218225380685" />
        <inertia ixx="0.0006091282503267632" iyy="3.808007809594227e-06" izz="0.0006091696409596878" ixy="3.0562993282023942e-09" iyz="-2.0830037034645643e-08" ixz="-6.206684514432903e-09" />
    </inertial>
    <visual name="front_left_wheel_shaft_visual">
        <origin xyz="0.47912081895680636 -0.1673319447386228 -0.14471234211626394" rpy="0.0 0.0 0.0" />
        <geometry>
            <mesh filename="file://$(find snow_white_description)/src/description/front_left_wheel_shaft.stl" scale="0.001 0.001 0.001" />
        </geometry>
    </visual>
    <collision name="front_left_wheel_shaft_collision">
        <origin xyz="0.47912081895680636 -0.1673319447386228 -0.14471234211626394" rpy="0.0 0.0 0.0" />
        <geometry>
            <mesh filename="file://$(find snow_white_description)/src/description/front_left_wheel_shaft.stl" scale="0.001 0.001 0.001" />
        </geometry>
    </collision>
</link>

<joint name="front_left_wheel_shaft_joint" type="fixed">
    <parent link="base_link"/>
    <child link="front_left_wheel_shaft_link"/>
    <origin xyz="-0.47912081895680636 0.1673319447386228 0.14471234211626394"/>
    <axis xyz="0 1 0"/>
</joint>

<gazebo reference="front_left_wheel_shaft_link">
  <mu1>0.2</mu1>
  <mu2>0.2</mu2>
  <self_collide>true</self_collide>
  <gravity>true</gravity>
</gazebo>

<link name="rear_right_wheel_shaft_link">
    <inertial>
        <origin xyz="-1.1655312345958795 -0.167331944738623 0.14471234211626424" rpy="0.0 0.0 0.0" />
        <mass value="0.08344218225380806" />
        <inertia ixx="0.0006091282503267667" iyy="3.80800781032975e-06" izz="0.0006091696409604441" ixy="3.056299137382812e-09" iyz="2.0830037032043558e-08" ixz="6.206684687037889e-09" />
    </inertial>
    <visual name="rear_right_wheel_shaft_visual">
        <origin xyz="1.1655312345958795 0.167331944738623 -0.14471234211626424" rpy="0.0 0.0 0.0" />
        <geometry>
            <mesh filename="file://$(find snow_white_description)/src/description/rear_right_wheel_shaft.stl" scale="0.001 0.001 0.001" />
        </geometry>
    </visual>
    <collision name="rear_right_wheel_shaft_collision">
        <origin xyz="1.1655312345958795 0.167331944738623 -0.14471234211626424" rpy="0.0 0.0 0.0" />
        <geometry>
            <mesh filename="file://$(find snow_white_description)/src/description/rear_right_wheel_shaft.stl" scale="0.001 0.001 0.001" />
        </geometry>
    </collision>
</link>

<joint name="rear_right_wheel_shaft_joint" type="fixed">
    <parent link="base_link"/>
    <child link="rear_right_wheel_shaft_link"/>
    <origin xyz="-1.1655312345958795 -0.167331944738623 0.14471234211626424"/>
    <axis xyz="0 1 0"/>
</joint>

<gazebo reference="rear_right_wheel_shaft_link">
  <mu1>0.2</mu1>
  <mu2>0.2</mu2>
  <self_collide>true</self_collide>
  <gravity>true</gravity>
</gazebo>

<link name="front_right_wheel_shaft_link">
    <inertial>
        <origin xyz="-0.47914138781272436 -0.1673319447386227 0.14477951870603134" rpy="0.0 0.0 0.0" />
        <mass value="0.08344218225380644" />
        <inertia ixx="0.0006091354666933405" iyy="3.8080078106524085e-06" izz="0.0006091624245941687" ixy="9.13023922265166e-09" iyz="-1.8970334230566932e-08" ixz="-1.6885997945401132e-08" />
    </inertial>
    <visual name="front_right_wheel_shaft_visual">
        <origin xyz="0.47914138781272436 0.1673319447386227 -0.14477951870603134" rpy="0.0 0.0 0.0" />
        <geometry>
            <mesh filename="file://$(find snow_white_description)/src/description/front_right_wheel_shaft.stl" scale="0.001 0.001 0.001" />
        </geometry>
    </visual>
    <collision name="front_right_wheel_shaft_collision">
        <origin xyz="0.47914138781272436 0.1673319447386227 -0.14477951870603134" rpy="0.0 0.0 0.0" />
        <geometry>
            <mesh filename="file://$(find snow_white_description)/src/description/front_right_wheel_shaft.stl" scale="0.001 0.001 0.001" />
        </geometry>
    </collision>
</link>

<joint name="front_right_wheel_shaft_link" type="fixed">
    <parent link="base_link"/>
    <child link="front_right_wheel_shaft_link"/>
    <origin xyz="-0.47914138781272436 -0.1673319447386227 0.14477951870603134"/>
    <axis xyz="0 1 0"/>
</joint>


<gazebo reference="front_right_wheel_shaft_link">
  <mu1>0.2</mu1>
  <mu2>0.2</mu2>
  <self_collide>true</self_collide>
  <gravity>true</gravity>
</gazebo>

<link name="augur_link">
    <inertial>
        <origin xyz="-0.11029548966368172 0.02590048066008034 0.25432357867980443" rpy="0.0 0.0 0.0" />
        <mass value="12.711996496928462" />
        <inertia ixx="0.6455148554536712" iyy="0.5147532627600199" izz="0.7120091781457232" ixy="0.021062793058903607" iyz="-0.015369752801326075" ixz="0.010211291313826865" />
    </inertial>
    <visual name="augur_visual">
        <origin xyz="0.11029548966368172 -0.02590048066008034 -0.25432357867980443" rpy="0.0 0.0 0.0" />
        <geometry>
            <mesh filename="file://$(find snow_white_description)/src/description/augur.stl" scale="0.001 0.001 0.001" />
        </geometry>
    </visual>
    <collision name="augur_collision">
        <origin xyz="0.11029548966368172 -0.02590048066008034 -0.25432357867980443" rpy="0.0 0.0 0.0" />
        <geometry>
            <mesh filename="file://$(find snow_white_description)/src/description/augur.stl" scale="0.001 0.001 0.001" />
        </geometry>
    </collision>
</link>

<joint name="augur_joint" type="fixed">
    <parent link="base_link"/>
    <child link="augur_link"/>
    <origin xyz="-0.11029548966368172 0.02590048066008034 0.25432357867980443"/>
    <axis xyz="0 1 0"/>
</joint>

<gazebo reference="augur_link">
  <mu1>0.2</mu1>
  <mu2>0.2</mu2>
  <self_collide>true</self_collide>
  <gravity>true</gravity>
</gazebo>

<link name="left_augur_wheel_link">
    <inertial>
        <origin xyz="-0.20802669205743962 0.20850000000000002 0.036129408344915244" rpy="0.0 0.0 0.0" />
        <mass value="0.22369587609978475" />
        <inertia ixx="0.00014323556448911194" iyy="0.00024914883141808654" izz="0.0001432355644891102" ixy="-3.469446951953614e-18" iyz="-4.336808689942018e-19" ixz="2.168404344971009e-19" />
    </inertial>
    <visual name="left_augur_wheel_visual">
        <origin xyz="0.20802669205743962 -0.20850000000000002 -0.036129408344915244" rpy="0.0 0.0 0.0" />
        <geometry>
            <mesh filename="file://$(find snow_white_description)/src/description/left_augur_wheel.stl" scale="0.001 0.001 0.001" />
        </geometry>
    </visual>
    <collision name="left_augur_wheel_collision">
        <origin xyz="0.20802669205743962 -0.20850000000000002 -0.036129408344915244" rpy="0.0 0.0 0.0" />
        <geometry>
            <mesh filename="file://$(find snow_white_description)/src/description/left_augur_wheel.stl" scale="0.001 0.001 0.001" />
        </geometry>
    </collision>
</link>

<joint name="left_augur_wheel_joint" type="continuous">
    <parent link="base_link"/>
    <child link="left_augur_wheel_link"/>
    <origin xyz="-0.20802669205743962 0.20850000000000002 0.036129408344915244"/>
    <axis xyz="0 1 0"/>
</joint>    

<gazebo reference="left_augur_wheel_link">
  <mu1>0.2</mu1>
  <mu2>0.2</mu2>
  <self_collide>true</self_collide>
  <gravity>true</gravity>
</gazebo>

<link name="right_augur_wheel_link">
    <inertial>
        <origin xyz="-0.20802669205743954 -0.23349999999999987 0.03612940834491524" rpy="0.0 0.0 0.0" />
        <mass value="0.22369587609978472" />
        <inertia ixx="0.00014323556448911368" iyy="0.00024914883141809695" izz="0.00014323556448912061" ixy="-3.469446951953614e-18" iyz="4.336808689942018e-19" ixz="6.505213034913027e-19" />
    </inertial>
    <visual name="right_augur_wheel_visual">
        <origin xyz="0.20802669205743954 0.23349999999999987 -0.03612940834491524" rpy="0.0 0.0 0.0" />
        <geometry>
            <mesh filename="file://$(find snow_white_description)/src/description/right_augur_wheel.stl" scale="0.001 0.001 0.001" />
        </geometry>
    </visual>
    <collision name="right_augur_wheel_collision">
        <origin xyz="0.20802669205743954 0.23349999999999987 -0.03612940834491524" rpy="0.0 0.0 0.0" />
        <geometry>
            <mesh filename="file://$(find snow_white_description)/src/description/right_augur_wheel.stl" scale="0.001 0.001 0.001" />
        </geometry>
    </collision>
</link>

<joint name="right_augur_wheel_joint" type="continuous">
    <parent link="base_link"/>
    <child link="right_augur_wheel_link"/>
    <origin xyz="-0.20802669205743954 -0.23349999999999987 0.03612940834491524"/>
    <axis xyz="0 1 0"/>
</joint>      

<gazebo reference="right_augur_wheel_link">
  <mu1>0.2</mu1>
  <mu2>0.2</mu2>
  <self_collide>true</self_collide>
  <gravity>true</gravity>
</gazebo> 

<link name="negative_x_ultrasonic_link">
    <inertial>
        <origin xyz="-1.2998767885185385 7.604018495665824e-13 0.33687612254746385" rpy="0.0 0.0 0.0" />
        <mass value="0.005935689883800179" />
        <inertia ixx="1.1934217042715734e-06" iyy="2.1557978977654324e-07" izz="1.1491025435159813e-06" ixy="-2.3331264761921873e-17" iyz="-4.656470363357838e-17" ixz="-4.746890645314361e-09" />
    </inertial>
    <visual name="negative_x_ultrasonic_visual">
        <origin xyz="1.2998767885185385 -7.604018495665824e-13 -0.33687612254746385" rpy="0.0 0.0 0.0" />
        <geometry>
            <mesh filename="file://$(find snow_white_description)/src/description/negative_x_ultrasonic.stl" scale="0.001 0.001 0.001" />
        </geometry>
    </visual>
    <collision name="negative_x_ultrasonic_collision">
        <origin xyz="1.2998767885185385 -7.604018495665824e-13 -0.33687612254746385" rpy="0.0 0.0 0.0" />
        <geometry>
            <mesh filename="file://$(find snow_white_description)/src/description/negative_x_ultrasonic.stl" scale="0.001 0.001 0.001" />
        </geometry>
    </collision>
</link>

<joint name="negative_x_ultrasonic_joint" type="fixed">
    <parent link="base_link"/>
    <child link="negative_x_ultrasonic_link"/>
    <origin xyz="-1.2998767885185385 7.604018495665824e-13 0.33687612254746385"/>
    <axis xyz="0 1 0"/>
</joint>


<gazebo reference="negative_x_ultrasonic_link">
  <mu1>0.2</mu1>
  <mu2>0.2</mu2>
  <self_collide>true</self_collide>
  <gravity>true</gravity>
</gazebo>

<link name="positive_y_ultrasonic_link">
    <inertial>
        <origin xyz="-0.8223259775185296 -0.20085081100080643 0.336876122547469" rpy="0.0 0.0 0.0" />
        <mass value="0.005935689883800049" />
        <inertia ixx="2.1557978977480852e-07" iyy="1.1934217042713566e-06" izz="1.149102543515114e-06" ixy="2.3418766925686896e-17" iyz="-4.7468906450433106e-09" ixz="4.683753385137379e-17" />
    </inertial>
    <visual name="positive_y_ultrasonic_visual">
        <origin xyz="0.8223259775185296 0.20085081100080643 -0.336876122547469" rpy="0.0 0.0 0.0" />
        <geometry>
            <mesh filename="file://$(find snow_white_description)/src/description/positive_y_ultrasonic.stl" scale="0.001 0.001 0.001" />
        </geometry>
    </visual>
    <collision name="positive_y_ultrasonic_collision">
        <origin xyz="0.8223259775185296 0.20085081100080643 -0.336876122547469" rpy="0.0 0.0 0.0" />
        <geometry>
            <mesh filename="file://$(find snow_white_description)/src/description/positive_y_ultrasonic.stl" scale="0.001 0.001 0.001" />
        </geometry>
    </collision>
</link>

<joint name="positive_y_ultrasonic_joint" type="fixed">
    <parent link="base_link"/>
    <child link="positive_y_ultrasonic_link"/>
    <origin xyz="-0.8223259775185296 -0.20085081100080643 0.336876122547469"/>
    <axis xyz="0 1 0"/>
</joint> 

<gazebo reference="positive_y_ultrasonic_link">
  <mu1>0.2</mu1>
  <mu2>0.2</mu2>
  <self_collide>true</self_collide>
  <gravity>true</gravity>
</gazebo>

<link name="negative_y_ultrasonic_link">
    <inertial>
        <origin xyz="-0.8223259775169315 0.20085081100077495 0.336876122547469" rpy="0.0 0.0 0.0" />
        <mass value="0.005935689883800058" />
        <inertia ixx="2.155797907636009e-07" iyy="1.1934217049409598e-06" izz="1.1491025431967922e-06" ixy="3.0357660829594124e-17" iyz="4.746890645097521e-09" ixz="-4.640385298237959e-17" />
    </inertial>
    <visual name="negative_y_ultrasonic_visual">
        <origin xyz="0.8223259775169315 -0.20085081100077495 -0.336876122547469" rpy="0.0 0.0 0.0" />
        <geometry>
            <mesh filename="file://$(find snow_white_description)/src/description/negative_y_ultrasonic.stl" scale="0.001 0.001 0.001" />
        </geometry>
    </visual>
    <collision name="negative_y_ultrasonic_collision">
        <origin xyz="0.8223259775169315 -0.20085081100077495 -0.336876122547469" rpy="0.0 0.0 0.0" />
        <geometry>
            <mesh filename="file://$(find snow_white_description)/src/description/negative_y_ultrasonic.stl" scale="0.001 0.001 0.001" />
        </geometry>
    </collision>
</link>

<joint name="negative_y_ultrasonic_joint" type="fixed">
    <parent link="base_link"/>
    <child link="negative_y_ultrasonic_link"/>
    <origin xyz="-0.8223259775169315 0.20085081100077495 0.336876122547469"/>
    <axis xyz="0 1 0"/>
</joint> 

<gazebo reference="negative_y_ultrasonic_link">
  <mu1>0.2</mu1>
  <mu2>0.2</mu2>
  <self_collide>true</self_collide>
  <gravity>true</gravity>
</gazebo>

<link name="imu_link">
  <visual>
    <geometry>
      <box size="0.020 0.027 0.004"/>
    </geometry>
  </visual>
  <collision>
    <geometry>
      <box size="0.020 0.027 0.004"/>
    </geometry>
  </collision>
</link>

<joint name="imu_joint" type="fixed">
  <parent link="base_link"/>
  <child link="imu_link"/>
  <origin xyz="-0.8261770190626948 -0.00019821739984704248 0.26183805471824457"/>
</joint>

<gazebo reference="imu_link">
    <sensor name="imu_sensor" type="imu">
        <plugin filename="libgazebo_ros_imu_sensor.so" name="imu_plugin">
            <ros>
                <namespace>/demo</namespace>
                <remapping>~/out:=imu</remapping>
            </ros>
            <initial_orientation_as_reference>false</initial_orientation_as_reference>
        </plugin>
        <always_on>true</always_on>
        <update_rate>100</update_rate>
        <visualize>true</visualize>
        <imu>
            <angular_velocity>
            <x>
                <noise type="gaussian">
                <mean>0.0</mean>
                <stddev>2e-4</stddev>
                <bias_mean>0.0000075</bias_mean>
                <bias_stddev>0.0000008</bias_stddev>
                </noise>
            </x>
            <y>
                <noise type="gaussian">
                <mean>0.0</mean>
                <stddev>2e-4</stddev>
                <bias_mean>0.0000075</bias_mean>
                <bias_stddev>0.0000008</bias_stddev>
                </noise>
            </y>
            <z>
                <noise type="gaussian">
                <mean>0.0</mean>
                <stddev>2e-4</stddev>
                <bias_mean>0.0000075</bias_mean>
                <bias_stddev>0.0000008</bias_stddev>
                </noise>
            </z>
            </angular_velocity>
            <linear_acceleration>
            <x>
                <noise type="gaussian">
                <mean>0.0</mean>
                <stddev>1.7e-2</stddev>
                <bias_mean>0.1</bias_mean>
                <bias_stddev>0.001</bias_stddev>
                </noise>
            </x>
            <y>
                <noise type="gaussian">
                <mean>0.0</mean>
                <stddev>1.7e-2</stddev>
                <bias_mean>0.1</bias_mean>
                <bias_stddev>0.001</bias_stddev>
                </noise>
            </y>
            <z>
                <noise type="gaussian">
                <mean>0.0</mean>
                <stddev>1.7e-2</stddev>
                <bias_mean>0.1</bias_mean>
                <bias_stddev>0.001</bias_stddev>
                </noise>
            </z>
            </linear_acceleration>
        </imu>
    </sensor>
</gazebo>

<link name="lidar_link">
    <inertial>
        <origin xyz="0.13500000000000056 -9.199892852992226e-17 0.4673180916632634" rpy="0.0 0.0 0.0" />
        <mass value="0.10503797555853478" />
        <inertia ixx="3.677889477625429e-05" iyy="3.677889477625776e-05" izz="4.3809267626510485e-05" ixy="-3.126388037344979e-20" iyz="-1.3874090584225174e-20" ixz="-2.6020852139652106e-18" />
    </inertial>
    <visual name="lidar_visual">
        <origin xyz="-0.13500000000000056 9.199892852992226e-17 -0.4673180916632634" rpy="0.0 0.0 0.0" />
        <geometry>
            <mesh filename="file://$(find snow_white_description)/src/description/lidar.stl" scale="0.001 0.001 0.001" />
        </geometry>
    </visual>
    <collision name="lidar_collision">
        <origin xyz="-0.13500000000000056 9.199892852992226e-17 -0.4673180916632634" rpy="0.0 0.0 0.0" />
        <geometry>
            <mesh filename="file://$(find snow_white_description)/src/description/lidar.stl" scale="0.001 0.001 0.001" />
        </geometry>
    </collision>
</link>

<joint name="lidar_joint" type="fixed">
    <parent link="base_link"/>
    <child link="lidar_link"/>
    <origin xyz="0.13500000000000056 -9.199892852992226e-17 0.4673180916632634"/>
    <axis xyz="0 1 0"/>
</joint> 

<gazebo reference="lidar_link">
  <sensor name="lidar" type="ray">
    <always_on>true</always_on>
    <visualize>true</visualize>
    <update_rate>5</update_rate>
    <ray>
      <scan>
        <horizontal>
          <samples>360</samples>
          <resolution>1.000000</resolution>
          <min_angle>0.000000</min_angle>
          <max_angle>6.280000</max_angle>
        </horizontal>
      </scan>
      <range>
        <min>0.0350000</min>
        <max>3.5</max>
        <resolution>0.015000</resolution>
      </range>
      <noise>
        <type>gaussian</type>
        <mean>0.0</mean>
        <stddev>0.01</stddev>
      </noise>
    </ray>
    <plugin name="scan" filename="libgazebo_ros_ray_sensor.so">
      <ros>
        <remapping>~/out:=scan</remapping>
      </ros>
      <output_type>sensor_msgs/LaserScan</output_type>
      <frame_name>lidar_link</frame_name>
    </plugin>
  </sensor>
  <self_collide>true</self_collide>
</gazebo>

<link name="camera_link" type="fixed">
    <inertial>
        <origin xyz="0.13500000000000056 -5.650065322205647e-17 0.41480000000000034" rpy="0.0 0.0 0.0" />
        <mass value="0.10060665783350226" />
        <inertia ixx="0.00013608620368398688" iyy="1.3396483310050555e-05" izz="0.0001377807190489585" ixy="5.1159076974724124e-20" iyz="1.5461409930139593e-19" ixz="-1.734723475976807e-18" />
    </inertial>
    <visual name="camera_visual">
        <origin xyz="-0.13500000000000056 5.650065322205647e-17 -0.41480000000000034" rpy="0.0 0.0 0.0" />
        <geometry>
            <mesh filename="file://$(find snow_white_description)/src/description/camera.stl" scale="0.001 0.001 0.001" />
        </geometry>
    </visual>
    <collision name="camera_collision">
        <origin xyz="-0.13500000000000056 5.650065322205647e-17 -0.41480000000000034" rpy="0.0 0.0 0.0" />
        <geometry>
            <mesh filename="file://$(find snow_white_description)/src/description/camera.stl" scale="0.001 0.001 0.001" />
        </geometry>
    </collision>
</link>

<joint name="camera_joint" type="fixed">
    <parent link="base_link"/>
    <child link="camera_link"/>
    <origin xyz="0.13500000000000056 -5.650065322205647e-17 0.41480000000000034"/>
    <axis xyz="0 1 0"/>
</joint>     

<link name="camera_depth_frame"/>

<joint name="camera_depth_joint" type="fixed">
  <origin xyz="0 0 0" rpy="${-pi/2} 0 ${-pi/2}"/>
  <parent link="camera_link"/>
  <child link="camera_depth_frame"/>
</joint>

<gazebo reference="camera_link">
  <sensor name="depth_camera" type="depth">
    <visualize>true</visualize>
    <update_rate>30.0</update_rate>
    <camera name="camera">
      <horizontal_fov>1.047198</horizontal_fov>
      <image>
        <width>640</width>
        <height>480</height>
        <format>R8G8B8</format>
      </image>
      <clip>
        <near>0.05</near>
        <far>3</far>
      </clip>
    </camera>
    <plugin name="depth_camera_controller" filename="libgazebo_ros_camera.so">
      <baseline>0.2</baseline>
      <alwaysOn>true</alwaysOn>
      <updateRate>0.0</updateRate>
      <frame_name>camera_depth_frame</frame_name>
      <pointCloudCutoff>0.5</pointCloudCutoff>
      <pointCloudCutoffMax>3.0</pointCloudCutoffMax>
      <distortionK1>0</distortionK1>
      <distortionK2>0</distortionK2>
      <distortionK3>0</distortionK3>
      <distortionT1>0</distortionT1>
      <distortionT2>0</distortionT2>
      <CxPrime>0</CxPrime>
      <Cx>0</Cx>
      <Cy>0</Cy>
      <focalLength>0</focalLength>
      <hackBaseline>0</hackBaseline>
    </plugin>
  </sensor>
  <self_collide>true</self_collide>
</gazebo>

<link name="e_stop_button_link">
    <inertial>
        <origin xyz="-1.2355259775176999 -6.62649864820291e-16 0.5031322262326828" rpy="0.0 0.0 0.0" />
        <mass value="0.12009477497850743" />
        <inertia ixx="5.098080769419186e-05" iyy="5.098080769425084e-05" izz="5.866826707850992e-05" ixy="5.534484742372518e-19" iyz="1.2214699964046478e-20" ixz="0.0" />
    </inertial>
    <visual name="e-stop-button_visual">
        <origin xyz="1.2355259775176999 6.62649864820291e-16 -0.5031322262326828" rpy="0.0 0.0 0.0" />
        <geometry>
            <mesh filename="file://$(find snow_white_description)/src/description/e-stop-button.stl" scale="0.001 0.001 0.001" />
        </geometry>
    </visual>
    <collision name="e-stop-button_collision">
        <origin xyz="1.2355259775176999 6.62649864820291e-16 -0.5031322262326828" rpy="0.0 0.0 0.0" />
        <geometry>
            <mesh filename="file://$(find snow_white_description)/src/description/e-stop-button.stl" scale="0.001 0.001 0.001" />
        </geometry>
    </collision>
</link>

<joint name="e_stop_button_joint" type="fixed">
    <parent link="base_link"/>
    <child link="e_stop_button_link"/>
    <origin xyz="-1.2355259775176999 -6.62649864820291e-16 0.5031322262326828"/>
    <axis xyz="0 1 0"/>
</joint> 

<gazebo reference="e_stop_button_link">
  <mu1>0.2</mu1>
  <mu2>0.2</mu2>
  <self_collide>true</self_collide>
  <gravity>true</gravity>
</gazebo>

<link name="top_light_link">
    <inertial>
        <origin xyz="-0.6551259775177494 -9.669489146408102e-17 0.5186703165352109" rpy="0.0 0.0 0.0" />
        <mass value="0.30568913579679863" />
        <inertia ixx="0.00023319431837760807" iyy="0.00023319431837762195" izz="0.0002093348875506773" ixy="2.1751423167432685e-18" iyz="1.039747724103695e-18" ixz="1.3877787807814457e-17" />
    </inertial>
    <visual name="top-light_visual">
        <origin xyz="0.6551259775177494 9.669489146408102e-17 -0.5186703165352109" rpy="0.0 0.0 0.0" />
        <geometry>
            <mesh filename="file://$(find snow_white_description)/src/description/top-light.stl" scale="0.001 0.001 0.001" />
        </geometry>
    </visual>
    <collision name="top-light_collision">
        <origin xyz="0.6551259775177494 9.669489146408102e-17 -0.5186703165352109" rpy="0.0 0.0 0.0" />
        <geometry>
            <mesh filename="file://$(find snow_white_description)/src/description/top-light.stl" scale="0.001 0.001 0.001" />
        </geometry>
    </collision>
</link>

<joint name="top_light_joint" type="fixed">
    <parent link="base_link"/>
    <child link="top_light_link"/>
    <origin xyz="-0.6551259775177494 -9.669489146408102e-17 0.5186703165352109"/>
    <axis xyz="0 1 0"/>
</joint> 

<gazebo reference="top_light_link">
  <mu1>0.2</mu1>
  <mu2>0.2</mu2>
  <self_collide>true</self_collide>
  <gravity>true</gravity>
</gazebo>

<gazebo>
  <plugin name='diff_drive' filename='libgazebo_ros_diff_drive.so'>
    <ros>
      <namespace>/demo</namespace>
    </ros>

    <left_joint>rear_left_wheel_joint</left_joint>
    <right_joint>rear_right_wheel_joint</right_joint>

    <wheel_separation>0.4</wheel_separation>
    <wheel_diameter>0.3302</wheel_diameter>

    <max_wheel_torque>20</max_wheel_torque>
    <max_wheel_acceleration>1.0</max_wheel_acceleration>

    <publish_odom>true</publish_odom>
    <publish_odom_tf>false</publish_odom_tf>
    <publish_wheel_tf>true</publish_wheel_tf>

    <odometry_frame>odom</odometry_frame>
    <robot_base_frame>base_link</robot_base_frame>
  </plugin>
</gazebo>

</robot>